
public class manejoExcepciones {

	public static void main(String[] args) {
		/* se generación una excepción porque en la sexta iteración del bucle se realiza la
		operación matemática 5/0 (infinito) y ese valor no puede ser almacenado en una
		variable de tipo int. Se arroja una excepción de tipo ArithmeticException y el programa
		se detiene en ese punto
		for(int i = -5; i < 5; i++) {
			int c = 5 / i;
			System.out.println(c);
		}*/
		/*
		Exception in thread "main" java.lang.ArithmeticException: / by zero
		at manejoExcepciones.main(manejoExcepciones.java:10)
		*/
		//Programa con TRY/CATCH
		// trata de ejecutar el código que se encuentra entre las llaves
		/*try {
			for(int i = -5; i < 5; i++) {
				int c = 5 / i;
				System.out.println(c);
			}
		}
		// captura la excepción de tipo ArithmeticException
		catch (ArithmeticException e) {
			System.out.println("Excepción arimética");
		}
		// captura cualquier otra excepción que pueda producirse
		catch (Exception e) {
			System.out.println("Otro error desconocido");
		}
		System.out.println("Programa finalizado");*/
		/*try {
			for (int i = -5; i < 5; i++) {
				if (i == 0) {
				// arroja explícitamente la excepción ArithmeticException, que es capturada por elcatch
					throw new ArithmeticException();
				}
				int c = 5 / i;
				System.out.println(c);
			}
		}
		// captura la excepción de tipo ArithmeticException
		catch (ArithmeticException e) {
			System.out.println("Excepción aritmética");
		}*/
		// trata de ejecutar el código que se encuentra entre las llaves
		/*try {
			for(int i = -5; i < 5; i++) {
				int c = 5 / i;
				System.out.println(c);
			}
		}
		// captura todas las excepciones que puedan producirse
		catch (Exception e) {
		// arroja la excepción ArithmeticException, que no es capturada
			System.out.println(5 / 0);
		}
		// este código se ejecuta siempre, se produzca excepción (dentro del bloque try o catch) o no
		finally {
			System.out.println("Este código se ejecuta siempre");
		}
		// esta línea no se ejecuta porque se produce una excepción no capturada dentro del catch
		System.out.println("Programa finalizado");*/
		//Uso de printStackTrace()
		try {
			for(int i = -5; i < 5; i++) {
				int c = 5 / i;
				System.out.println(c);
			}
		}
		// captura cualquier excepción que pueda producirse
		catch (Exception e) {
			e.printStackTrace();
		}
		System.out.println("El programa puede continuar a partir de aqui");
	}
}